<?xml version="1.0" ?>
<!-- =================================================================================== -->
<!-- |    This document was autogenerated by xacro from differential_robot.urdf.xacro  | -->
<!-- |    EDITING THIS FILE BY HAND IS NOT RECOMMENDED                                 | -->
<!-- =================================================================================== -->
<robot name="three_wheeled_car">
  <link name="base_link">
    <visual>
      <geometry>
        <cylinder length="0.023999999999999997" radius="0.175"/>
      </geometry>
      <material name="red">
        <color rgba="0.8 0 0 0.5"/>
      </material>
    </visual>
    <collision>
      <geometry>
        <cylinder length="0.023999999999999997" radius="0.175"/>
      </geometry>
    </collision>
    <inertial>
      <mass value="0.2"/>
      <origin rpy="0 0 0"/>
      <inertia ixx="0.0015408499999999996" ixy="0.0" ixz="0.0" iyy="0.0015408499999999996" iyz="0.0" izz="0.0030624999999999997"/>
    </inertial>
  </link>
  <link name="base_footprint">
    </link>
  <joint name="footprint_to_base" type="fixed">
    <parent link="base_footprint"/>
    <child link="base_link"/>
    <origin rpy="0 0 0" xyz="0 0 0.036"/>
  </joint>
  <link name="right_wheel">
    <visual>
      <geometry>
        <cylinder length="0.008" radius="0.036"/>
      </geometry>
      <material name="black">
        <color rgba="0 0 0 0.5"/>
      </material>
    </visual>
    <collision>
      <geometry>
        <cylinder length="0.008" radius="0.036"/>
      </geometry>
    </collision>
    <inertial>
      <mass value="0.025"/>
      <origin rpy="0 0 0"/>
      <inertia ixx="8.233333333333331e-06" ixy="0.0" ixz="0.0" iyy="8.233333333333331e-06" iyz="0.0" izz="1.6199999999999997e-05"/>
    </inertial>
  </link>
  <link name="left_wheel">
    <visual>
      <geometry>
        <cylinder length="0.008" radius="0.036"/>
      </geometry>
      <material name="black">
        <color rgba="0 0 0 0.5"/>
      </material>
    </visual>
    <collision>
      <geometry>
        <cylinder length="0.008" radius="0.036"/>
      </geometry>
    </collision>
    <inertial>
      <mass value="0.025"/>
      <origin rpy="0 0 0"/>
      <inertia ixx="8.233333333333331e-06" ixy="0.0" ixz="0.0" iyy="8.233333333333331e-06" iyz="0.0" izz="1.6199999999999997e-05"/>
    </inertial>
  </link>
  <joint name="base_to_right_wheel" type="continuous">
    <parent link="base_link"/>
    <child link="right_wheel"/>
    <origin rpy="-1.57 0 0" xyz="0 -0.179 0"/>
    <axis xyz="0 0 1"/>
  </joint>
  <joint name="base_to_left_wheel" type="continuous">
    <parent link="base_link"/>
    <child link="left_wheel"/>
    <origin rpy="-1.57 0 0" xyz="0 0.179 0"/>
    <axis xyz="0 0 1"/>
  </joint>
  <link name="head">
    <visual>
      <geometry>
        <box size="0.03 0.03 0.03"/>
      </geometry>
      <material name="blue">
        <color rgba="0 0 1 0.5"/>
      </material>
    </visual>
    <collision>
      <geometry>
        <box size="0.03 0.03 0.03"/>
      </geometry>
    </collision>
    <inertial>
      <mass value="0.02"/>
      <origin rpy="0 0 0"/>
      <inertia ixx="2.9999999999999997e-06" ixy="0.0" ixz="0.0" iyy="2.9999999999999997e-06" iyz="0.0" izz="2.9999999999999997e-06"/>
    </inertial>
  </link>
  <joint name="base_to_head" type="fixed">
    <parent link="base_link"/>
    <child link="head"/>
    <origin rpy="0 0 0" xyz="0.15399999999999997 0 0.026999999999999996"/>
  </joint>
  <link name="passive_wheel_holder">
    <visual>
      <geometry>
        <cylinder length="0.011999999999999997" radius="0.012"/>
      </geometry>
      <material name="white">
        <color rgba="1 1 1 0.5"/>
      </material>
    </visual>
    <collision>
      <geometry>
        <cylinder length="0.011999999999999997" radius="0.012"/>
      </geometry>
    </collision>
    <inertial>
      <mass value="0.015"/>
      <origin rpy="0 0 0"/>
      <inertia ixx="7.199999999999999e-07" ixy="0.0" ixz="0.0" iyy="7.199999999999999e-07" iyz="0.0" izz="1.0799999999999998e-06"/>
    </inertial>
  </link>
  <joint name="base_to_passive_wheel_holder" type="fixed">
    <parent link="base_link"/>
    <child link="passive_wheel_holder"/>
    <origin rpy="0 0 0" xyz="0.15399999999999997 0 -0.017999999999999995"/>
  </joint>
  <link name="passive_wheel">
    <visual>
      <geometry>
        <sphere radius="0.012"/>
      </geometry>
      <material name="white">
        <color rgba="1 1 1 0.5"/>
      </material>
    </visual>
    <collision>
      <geometry>
        <sphere radius="0.012"/>
      </geometry>
    </collision>
    <inertial>
      <mass value="0.01"/>
      <origin rpy="0 0 0"/>
      <inertia ixx="5.76e-07" ixy="0.0" ixz="0.0" iyy="5.76e-07" iyz="0.0" izz="5.76e-07"/>
    </inertial>
  </link>
  <joint name="passive_wheel_holder_to_passive_wheel" type="fixed">
    <parent link="passive_wheel_holder"/>
    <child link="passive_wheel"/>
    <origin rpy="0 0 0" xyz="0 0 -0.005999999999999998"/>
  </joint>
  <link name="left_wheel_indicator_1">
    <visual>
      <geometry>
        <box size="0.01 0.01 0.001"/>
      </geometry>
      <material name="cyan">
        <color rgba="0 1 1 1"/>
      </material>
    </visual>
  </link>
  <link name="left_wheel_indicator_2">
    <visual>
      <geometry>
        <box size="0.01 0.01 0.001"/>
      </geometry>
      <material name="cyan">
        <color rgba="0 1 1 1"/>
      </material>
    </visual>
  </link>
  <link name="left_wheel_indicator_3">
    <visual>
      <geometry>
        <box size="0.01 0.01 0.001"/>
      </geometry>
      <material name="cyan">
        <color rgba="0 1 1 1"/>
      </material>
    </visual>
  </link>
  <link name="right_wheel_indicator_1">
    <visual>
      <geometry>
        <box size="0.01 0.01 0.001"/>
      </geometry>
      <material name="cyan">
        <color rgba="0 1 1 1"/>
      </material>
    </visual>
  </link>
  <link name="right_wheel_indicator_2">
    <visual>
      <geometry>
        <box size="0.01 0.01 0.001"/>
      </geometry>
      <material name="cyan">
        <color rgba="0 1 1 1"/>
      </material>
    </visual>
  </link>
  <link name="right_wheel_indicator_3">
    <visual>
      <geometry>
        <box size="0.01 0.01 0.001"/>
      </geometry>
      <material name="cyan">
        <color rgba="0 1 1 1"/>
      </material>
    </visual>
  </link>
  <joint name="left_wheel_to_left_wheel_indicator_1" type="fixed">
    <parent link="left_wheel"/>
    <child link="left_wheel_indicator_1"/>
    <origin rpy="0 0 0" xyz="0 -0.030999999999999996 0.0045000000000000005"/>
  </joint>
  <joint name="left_wheel_to_left_wheel_indicator_2" type="fixed">
    <parent link="left_wheel"/>
    <child link="left_wheel_indicator_2"/>
    <origin rpy="0 0 2.0943951023931953" xyz="0.026846787517317592 0.015500000000000002 0.0045000000000000005"/>
  </joint>
  <joint name="left_wheel_to_left_wheel_indicator_3" type="fixed">
    <parent link="left_wheel"/>
    <child link="left_wheel_indicator_3"/>
    <origin rpy="0 0 -2.0943951023931953" xyz="-0.026846787517317592 0.015500000000000002 0.0045000000000000005"/>
  </joint>
  <joint name="right_wheel_to_right_wheel_indicator_1" type="fixed">
    <parent link="right_wheel"/>
    <child link="right_wheel_indicator_1"/>
    <origin rpy="0 0 0" xyz="0 -0.030999999999999996 -0.0045000000000000005"/>
  </joint>
  <joint name="right_wheel_to_right_wheel_indicator_2" type="fixed">
    <parent link="right_wheel"/>
    <child link="right_wheel_indicator_2"/>
    <origin rpy="0 0 2.0943951023931953" xyz="0.026846787517317592 0.015500000000000002 -0.0045000000000000005"/>
  </joint>
  <joint name="right_wheel_to_right_wheel_indicator_3" type="fixed">
    <parent link="right_wheel"/>
    <child link="right_wheel_indicator_3"/>
    <origin rpy="0 0 -2.0943951023931953" xyz="-0.026846787517317592 0.015500000000000002 -0.0045000000000000005"/>
  </joint>
</robot>
